<?xml version="1.0" ?>
<!-- =================================================================================== -->
<!-- |    This document was autogenerated by xacro from /home/elu1652/ros2_ws/src/rover-2025/sim/model/rover.urdf.xacro | -->
<!-- |    EDITING THIS FILE BY HAND IS NOT RECOMMENDED                                 | -->
<!-- =================================================================================== -->
<robot name="rover">
  <model name="kinect">
    <link name="kinect_link">
      <inertial>
        <mass>0.1</mass>
        <inertia>
          <ixx>0</ixx>
          <ixy>0</ixy>
          <ixz>0</ixz>
          <iyy>0</iyy>
          <iyz>0</iyz>
          <izz>0</izz>
        </inertia>
      </inertial>
      <collision name="kinect_collision">
        <pose>0 0 0 0 0 0</pose>
        <geometry>
          <box>
            <size>0.073 0.276 0.072</size>
          </box>
        </geometry>
      </collision>
      <visual name="kinect_visual">
        <pose>0 0 0 0 0 0</pose>
        <geometry>
          <mesh>
            <uri>file://meshes/depth_camera.dae</uri>
            <scale>1.0 1.0 1.0</scale>
          </mesh>
        </geometry>
      </visual>
      <sensor name="camera" type="depth_camera">
        <pose>0 0 0 0 0 0</pose>
        <update_rate>20</update_rate>
        <depth_camera>
          <horizontal_fov>1.047198</horizontal_fov>
          <image>
            <width>640</width>
            <height>480</height>
            <format>R8G8B8</format>
          </image>
          <clip>
            <near>0.05</near>
            <far>3</far>
          </clip>
        </depth_camera>
        <plugin filename="ignition-gazebo-depth-camera-system" name="ignition::sensors::DepthCameraSensor">
          <topic>/camera/depth/image_raw</topic>
          <camera_info_topic>/camera/depth/camera_info</camera_info_topic>
          <point_cloud_topic>/camera/depth/points</point_cloud_topic>
          <frame_id>camera_link</frame_id>
        </plugin>
      </sensor>
    </link>
    <joint name="depth_camera_joint" type="fixed">
      <parent>parent_link</parent>
      <child>kinect_link</child>
      <pose>0 0 0 0 0 0</pose>
    </joint>
  </model>
  <link name="imu_link"/>
  <joint name="imu_to_chassis" type="fixed">
    <parent link="chassis_link"/>
    <child link="imu_link"/>
    <origin rpy="0 0 0" xyz="0 0 0"/>
  </joint>
  <gazebo reference="imu_link">
    <sensor name="imu" type="imu">
      <always_on>1</always_on>
      <update_rate>50</update_rate>
      <visualize>true</visualize>
      <topic>/imu/data</topic>
      <enable_metrics>true</enable_metrics>
      <ignition_frame_id>imu_link</ignition_frame_id>
    </sensor>
  </gazebo>
  <gazebo>
    <plugin filename="libignition-gazebo-imu-system" name="ignition::gazebo::systems::Imu"/>
  </gazebo>
  <link name="lidar_link">
    <visual>
      <origin rpy="-1.57 0 3.1415" xyz="0 0 0"/>
      <geometry>
        <!-- A simple cylinder to represent the LiDAR -->
        <cylinder length="0.1" radius="0.05"/>
      </geometry>
      <material name="black">
        <color rgba="0.0 0.0 0.0 1.0"/>
      </material>
    </visual>
    <collision>
      <origin rpy="-1.57 0 3.1415" xyz="0 0 0"/>
    </collision>
  </link>
  <joint name="lidar_to_chassis" type="fixed">
    <parent link="chassis_link"/>
    <child link="lidar_link"/>
    <origin rpy="0 0 3.1415" xyz="0.174 0 0.10"/>
  </joint>
  <gazebo reference="lidar_link">
    <sensor name="gpu_lidar" type="gpu_lidar">
      <pose>0 0 0 0 0 0</pose>
      <topic>scan</topic>
      <ignition_frame_id>lidar_link</ignition_frame_id>
      <update_rate>10</update_rate>
      <lidar>
        <scan>
          <horizontal>
            <samples>640</samples>
            <resolution>1</resolution>
            <min_angle>-3.14159</min_angle>
            <max_angle>3.14159</max_angle>
          </horizontal>
          <vertical>
            <samples>1</samples>
            <resolution>1</resolution>
            <min_angle>0.0</min_angle>
            <max_angle>0.0</max_angle>
          </vertical>
        </scan>
        <range>
          <min>0.15</min>
          <max>10.0</max>
          <resolution>0.01</resolution>
        </range>
      </lidar>
      <visualize>true</visualize>
    </sensor>
  </gazebo>
  <gazebo>
    <plugin filename="libignition-gazebo-sensors-system.so" name="ignition::gazebo::systems::Sensors">
      <render_engine>ogre2</render_engine>
    </plugin>
  </gazebo>
  <link name="camera_link"/>
  <joint name="camera_to_chassis" type="fixed">
    <parent link="chassis_link"/>
    <child link="camera_link"/>
    <origin rpy="0 0 -1.570796325" xyz="0 0 0"/>
    <!-- Collision block commented out for now -->
    <!-- <collision name="collision">
            <geometry>
                <cylinder>
                    <radius>0.05</radius>
                    <length>0.2</length>
                </cylinder>
            </geometry>
        </collision> -->
    <visual name="camera_visual">
      <geometry>
        <cylinder>
          <radius>1</radius>
          <length>2</length>
        </cylinder>
      </geometry>
      <material>
        <color rgba="0 0 1 1"/>
        <!-- Blue color for the camera -->
      </material>
    </visual>
  </joint>
  <gazebo reference="camera_link">
    <sensor name="camera" type="camera">
      <topic>camera</topic>
      <pose>0 0 0 0 0 0</pose>
      <visualize>true</visualize>
      <update_rate>20</update_rate>
      <camera>
        <horizontal_fov>1.047198</horizontal_fov>
        <image>
          <format>R8G8B8</format>
          <width>640</width>
          <height>480</height>
        </image>
        <clip>
          <near>0.05</near>
          <far>3</far>
        </clip>
      </camera>
    </sensor>
  </gazebo>
  <gazebo>
    <!-- Plugin for rendering engine, commented out for now -->
    <!-- <plugin
            filename="ignition-gazebo-sensors-system"
            name="ignition::gazebo::systems::Sensors">
            <render_engine>ogre2</render_engine>
        </plugin> -->
  </gazebo>
  <!-- <xacro:include filename="$(find sim)/model/thermal_camera.urdf" /> -->
  <!-- Robot Definition -->
  <link name="base_link"/>
  <link name="chassis_link">
    <visual>
      <origin rpy="0 0 0" xyz="0 0 0.1"/>
      <geometry>
        <mesh filename="file:///home/elu1652/ros2_ws/src/rover-2025/install/sim/share/sim/model/meshes/Full_Asm_noarm_mast_cam.dae"/>
      </geometry>
    </visual>
    <collision>
      <origin rpy="0 0 0" xyz="0 0 0.2"/>
      <geometry>
        <!-- <mesh
                    filename="file://$(find sim)/model/meshes/Full_Asm_Adjusted.dae" /> -->
        <box size="0.4 0.6 0.3"/>
      </geometry>
    </collision>
    <inertial>
      <origin rpy="0 0 0" xyz="0 0 0"/>
      <mass value="45.2"/>
      <!-- TODO FIXME The inertia below is invalid, using dummy 0 inertia -->
      <!-- <inertia ixx="1.7724" ixy="0.0" ixz="0.0" iyy="0.141558" iyz="-0.0" izz="0.179826"
            /> -->
      <!-- <inertia ixx="0.0" ixy="0.0" ixz="0.0" iyy="0.0" iyz="0.0" izz="0.0" /> -->
      <inertia ixx="1.3569" ixy="0.0" ixz="0.0" iyy="1.924" iyz="0.0" izz="0.847"/>
    </inertial>
  </link>
  <joint name="base_to_chassis" type="fixed">
    <parent link="base_link"/>
    <child link="chassis_link"/>
    <origin xyz="0 0 0.2"/>
  </joint>
  <!-- Wheel Link -->
  <link name="lf_wheel_link">
    <inertial>
      <mass value="1.2"/>
      <origin xyz="0 0 0"/>
      <!-- <inertia  ixx="0" ixy="0" ixz="0" iyy="0" iyz="0" izz="0" /> -->
      <!-- <inertia ixx="0.142" ixy="0.0003118" ixz="0.0000392177" iyy="0.14155823"
					iyz="-0.000062645" izz="1.3729" /> -->
      <inertia ixx="0.05" ixy="0.0" ixz="0.0" iyy="0.05" iyz="0.0" izz="0.01"/>
    </inertial>
    <visual>
      <origin rpy="1.570796325 0 0" xyz="0 0 0"/>
      <geometry>
        <mesh filename="file:///home/elu1652/ros2_ws/src/rover-2025/install/sim/share/sim/model/meshes/WHEEL.dae"/>
      </geometry>
    </visual>
    <collision>
      <!-- <origin xyz="0.03 0 0" rpy="${M_PI/2} ${M_PI/2} 0" /> -->
      <origin rpy="0 0 0" xyz="0 0 0"/>
      <geometry>
        <cylinder length="0.2" radius="0.15"/>
      </geometry>
    </collision>
  </link>
  <!-- Wheel Joint -->
  <joint name="lf_wheel" type="continuous">
    <parent link="chassis_link"/>
    <child link="lf_wheel_link"/>
    <origin rpy="0 1.570796325 0" xyz="0.5125 -0.316275 0.039248000000000005"/>
    <axis xyz="0 0 1"/>
    <limit effort="300" velocity="50.0"/>
    <!-- <dynamics damping="1" friction="100.0" /> -->
  </joint>
  <gazebo reference="lf_wheel_link">
    <mu1 value="5"/>
    <mu2 value="5"/>
    <kp value="10000000.0"/>
    <kd value="1.0"/>
    <material>Gazebo/Grey</material>
  </gazebo>
  <transmission name="lf_wheel_trans">
    <type>transmission_interface/SimpleTransmission</type>
    <actuator name="lf_wheel_motor">
      <mechanicalReduction>1</mechanicalReduction>
    </actuator>
    <joint name="lf_wheel">
      <hardwareInterface>hardware_interface/VelocityJointInterface</hardwareInterface>
    </joint>
  </transmission>
  <!-- Wheel Link -->
  <link name="rf_wheel_link">
    <inertial>
      <mass value="1.2"/>
      <origin xyz="0 0 0"/>
      <!-- <inertia  ixx="0" ixy="0" ixz="0" iyy="0" iyz="0" izz="0" /> -->
      <!-- <inertia ixx="0.142" ixy="0.0003118" ixz="0.0000392177" iyy="0.14155823"
					iyz="-0.000062645" izz="1.3729" /> -->
      <inertia ixx="0.05" ixy="0.0" ixz="0.0" iyy="0.05" iyz="0.0" izz="0.01"/>
    </inertial>
    <visual>
      <origin rpy="1.570796325 0 0" xyz="0 0 0"/>
      <geometry>
        <mesh filename="file:///home/elu1652/ros2_ws/src/rover-2025/install/sim/share/sim/model/meshes/WHEEL.dae"/>
      </geometry>
    </visual>
    <collision>
      <!-- <origin xyz="0.03 0 0" rpy="${M_PI/2} ${M_PI/2} 0" /> -->
      <origin rpy="0 0 0" xyz="0 0 0"/>
      <geometry>
        <cylinder length="0.2" radius="0.15"/>
      </geometry>
    </collision>
  </link>
  <!-- Wheel Joint -->
  <joint name="rf_wheel" type="continuous">
    <parent link="chassis_link"/>
    <child link="rf_wheel_link"/>
    <origin rpy="0 1.570796325 0" xyz="-0.5125 -0.316275 0.039248000000000005"/>
    <axis xyz="0 0 1"/>
    <limit effort="300" velocity="50.0"/>
    <!-- <dynamics damping="1" friction="100.0" /> -->
  </joint>
  <gazebo reference="rf_wheel_link">
    <mu1 value="5"/>
    <mu2 value="5"/>
    <kp value="10000000.0"/>
    <kd value="1.0"/>
    <material>Gazebo/Grey</material>
  </gazebo>
  <transmission name="rf_wheel_trans">
    <type>transmission_interface/SimpleTransmission</type>
    <actuator name="rf_wheel_motor">
      <mechanicalReduction>1</mechanicalReduction>
    </actuator>
    <joint name="rf_wheel">
      <hardwareInterface>hardware_interface/VelocityJointInterface</hardwareInterface>
    </joint>
  </transmission>
  <!-- Wheel Link -->
  <link name="lb_wheel_link">
    <inertial>
      <mass value="1.2"/>
      <origin xyz="0 0 0"/>
      <!-- <inertia  ixx="0" ixy="0" ixz="0" iyy="0" iyz="0" izz="0" /> -->
      <!-- <inertia ixx="0.142" ixy="0.0003118" ixz="0.0000392177" iyy="0.14155823"
					iyz="-0.000062645" izz="1.3729" /> -->
      <inertia ixx="0.05" ixy="0.0" ixz="0.0" iyy="0.05" iyz="0.0" izz="0.01"/>
    </inertial>
    <visual>
      <origin rpy="1.570796325 0 0" xyz="0 0 0"/>
      <geometry>
        <mesh filename="file:///home/elu1652/ros2_ws/src/rover-2025/install/sim/share/sim/model/meshes/WHEEL.dae"/>
      </geometry>
    </visual>
    <collision>
      <!-- <origin xyz="0.03 0 0" rpy="${M_PI/2} ${M_PI/2} 0" /> -->
      <origin rpy="0 0 0" xyz="0 0 0"/>
      <geometry>
        <cylinder length="0.2" radius="0.15"/>
      </geometry>
    </collision>
  </link>
  <!-- Wheel Joint -->
  <joint name="lb_wheel" type="continuous">
    <parent link="chassis_link"/>
    <child link="lb_wheel_link"/>
    <origin rpy="0 1.570796325 0" xyz="0.5125 0.306875 0.039248000000000005"/>
    <axis xyz="0 0 1"/>
    <limit effort="300" velocity="50.0"/>
    <!-- <dynamics damping="1" friction="100.0" /> -->
  </joint>
  <gazebo reference="lb_wheel_link">
    <mu1 value="5"/>
    <mu2 value="5"/>
    <kp value="10000000.0"/>
    <kd value="1.0"/>
    <material>Gazebo/Grey</material>
  </gazebo>
  <transmission name="lb_wheel_trans">
    <type>transmission_interface/SimpleTransmission</type>
    <actuator name="lb_wheel_motor">
      <mechanicalReduction>1</mechanicalReduction>
    </actuator>
    <joint name="lb_wheel">
      <hardwareInterface>hardware_interface/VelocityJointInterface</hardwareInterface>
    </joint>
  </transmission>
  <!-- Wheel Link -->
  <link name="rb_wheel_link">
    <inertial>
      <mass value="1.2"/>
      <origin xyz="0 0 0"/>
      <!-- <inertia  ixx="0" ixy="0" ixz="0" iyy="0" iyz="0" izz="0" /> -->
      <!-- <inertia ixx="0.142" ixy="0.0003118" ixz="0.0000392177" iyy="0.14155823"
					iyz="-0.000062645" izz="1.3729" /> -->
      <inertia ixx="0.05" ixy="0.0" ixz="0.0" iyy="0.05" iyz="0.0" izz="0.01"/>
    </inertial>
    <visual>
      <origin rpy="1.570796325 0 0" xyz="0 0 0"/>
      <geometry>
        <mesh filename="file:///home/elu1652/ros2_ws/src/rover-2025/install/sim/share/sim/model/meshes/WHEEL.dae"/>
      </geometry>
    </visual>
    <collision>
      <!-- <origin xyz="0.03 0 0" rpy="${M_PI/2} ${M_PI/2} 0" /> -->
      <origin rpy="0 0 0" xyz="0 0 0"/>
      <geometry>
        <cylinder length="0.2" radius="0.15"/>
      </geometry>
    </collision>
  </link>
  <!-- Wheel Joint -->
  <joint name="rb_wheel" type="continuous">
    <parent link="chassis_link"/>
    <child link="rb_wheel_link"/>
    <origin rpy="0 1.570796325 0" xyz="-0.5125 0.306875 0.039248000000000005"/>
    <axis xyz="0 0 1"/>
    <limit effort="300" velocity="50.0"/>
    <!-- <dynamics damping="1" friction="100.0" /> -->
  </joint>
  <gazebo reference="rb_wheel_link">
    <mu1 value="5"/>
    <mu2 value="5"/>
    <kp value="10000000.0"/>
    <kd value="1.0"/>
    <material>Gazebo/Grey</material>
  </gazebo>
  <transmission name="rb_wheel_trans">
    <type>transmission_interface/SimpleTransmission</type>
    <actuator name="rb_wheel_motor">
      <mechanicalReduction>1</mechanicalReduction>
    </actuator>
    <joint name="rb_wheel">
      <hardwareInterface>hardware_interface/VelocityJointInterface</hardwareInterface>
    </joint>
  </transmission>
  <!-- <xacro:depth_camera parent_link="chassis_link">
        <origin xyz="0 -0.41 0.32" rpy="0 0 -1.57079" />
    </xacro:depth_camera> -->
  <!-- Base link is the center of the robot's bottom plate -->
  <joint name="MR_arm_joint" type="fixed">
    <parent link="chassis_link"/>
    <child link="link_0_base_waist"/>
    <origin rpy="0 0 -1.57079" xyz="0 -0.28 0.37"/>
  </joint>
  <link name="link_0_base_waist">
    <inertial>
      <mass value="0.1"/>
      <origin rpy="0 0 0" xyz="0 0 0"/>
      <inertia ixx="0.0001" ixy="0" ixz="0" iyy="0.0001" iyz="0" izz="0.0002"/>
      <gravity>0</gravity>
      <self_collide>0</self_collide>
    </inertial>
    <visual>
      <origin rpy="0 0 0" xyz="0 0 0"/>
      <geometry>
        <mesh filename="file:///home/elu1652/ros2_ws/src/rover-2025/install/sim/share/sim/model/meshes/Link0.stl"/>
      </geometry>
    </visual>
    <collision>
      <origin rpy="0 0 0" xyz="0 0 0"/>
      <geometry>
        <mesh filename="file:///home/elu1652/ros2_ws/src/rover-2025/install/sim/share/sim/model/meshes/collision_Link0.stl"/>
      </geometry>
    </collision>
  </link>
  <joint name="joint_waist" type="revolute">
    <origin rpy="0 0 0" xyz="0 0 0"/>
    <parent link="link_0_base_waist"/>
    <child link="link_1_waist_shoulder"/>
    <axis xyz="0 0 1"/>
    <limit effort="10.0" lower="-3.141592" upper="3.141592" velocity="2.61799"/>
    <dynamics damping="0.5"/>
  </joint>
  <!-- Joint 1 -->
  <link name="link_1_waist_shoulder">
    <inertial>
      <mass value="0.1"/>
      <origin rpy="0 0 0" xyz="0 0 0"/>
      <inertia ixx="0.0001" ixy="0" ixz="0" iyy="0.0001" iyz="0" izz="0.0002"/>
      <gravity>0</gravity>
      <self_collide>0</self_collide>
    </inertial>
    <visual>
      <origin rpy="0 0 0" xyz="0 0 0"/>
      <geometry>
        <mesh filename="file:///home/elu1652/ros2_ws/src/rover-2025/install/sim/share/sim/model/meshes/Link1.stl"/>
      </geometry>
    </visual>
    <collision>
      <origin rpy="0 0 0" xyz="0 0 0"/>
      <geometry>
        <mesh filename="file:///home/elu1652/ros2_ws/src/rover-2025/install/sim/share/sim/model/meshes/collision_Link1.stl"/>
      </geometry>
    </collision>
  </link>
  <joint name="joint_shoulder" type="revolute">
    <origin rpy="0 0 0" xyz="0 0 0.0575"/>
    <parent link="link_1_waist_shoulder"/>
    <child link="link_2_shoulder_elbow"/>
    <axis xyz="0 1 0"/>
    <limit effort="10.0" lower="-1.570796327" upper="1.570796327" velocity="2.61799"/>
    <dynamics damping="0.5"/>
  </joint>
  <link name="link_2_shoulder_elbow">
    <inertial>
      <mass value="0.1"/>
      <origin rpy="0 0 0" xyz="0 0 0"/>
      <inertia ixx="0.0001" ixy="0" ixz="0" iyy="0.0001" iyz="0" izz="0.0002"/>
      <gravity>0</gravity>
      <self_collide>0</self_collide>
    </inertial>
    <visual>
      <origin rpy="0 0 0" xyz="0 0 0"/>
      <geometry>
        <mesh filename="file:///home/elu1652/ros2_ws/src/rover-2025/install/sim/share/sim/model/meshes/Link2.stl"/>
      </geometry>
    </visual>
    <collision>
      <origin rpy="0 0 0" xyz="0 0 0"/>
      <geometry>
        <mesh filename="file:///home/elu1652/ros2_ws/src/rover-2025/install/sim/share/sim/model/meshes/collision_Link2.stl"/>
      </geometry>
    </collision>
  </link>
  <joint name="joint_elbow" type="revolute">
    <origin rpy="0 0 0" xyz="0 0 0.5"/>
    <parent link="link_2_shoulder_elbow"/>
    <child link="link_3_elbow_wrist_pitch"/>
    <axis xyz="0 1 0"/>
    <limit effort="10.0" lower="-1.570796327" upper="1.570796327" velocity="2.61799"/>
    <dynamics damping="0.5"/>
  </joint>
  <link name="link_3_elbow_wrist_pitch">
    <inertial>
      <mass value="0.1"/>
      <origin rpy="0 0 0" xyz="0 0 0"/>
      <inertia ixx="0.0001" ixy="0" ixz="0" iyy="0.0001" iyz="0" izz="0.0002"/>
      <gravity>0</gravity>
      <self_collide>0</self_collide>
    </inertial>
    <visual>
      <origin rpy="0 0 0" xyz="0 0 0"/>
      <geometry>
        <mesh filename="file:///home/elu1652/ros2_ws/src/rover-2025/install/sim/share/sim/model/meshes/Link3.stl"/>
      </geometry>
    </visual>
    <collision>
      <origin rpy="0 0 0" xyz="0 0 0"/>
      <geometry>
        <mesh filename="file:///home/elu1652/ros2_ws/src/rover-2025/install/sim/share/sim/model/meshes/collision_Link3.stl"/>
      </geometry>
    </collision>
  </link>
  <joint name="joint_wrist_pitch" type="revolute">
    <origin rpy="0 0 0" xyz="0.4 0 0"/>
    <parent link="link_3_elbow_wrist_pitch"/>
    <child link="link_4_wrist_pitch_wrist_roll"/>
    <axis xyz="0 1 0"/>
    <limit effort="10.0" lower="-1.570796327" upper="1.570796327" velocity="2.61799"/>
    <dynamics damping="0.5"/>
  </joint>
  <link name="link_4_wrist_pitch_wrist_roll">
    <inertial>
      <mass value="0.1"/>
      <origin rpy="0 0 0" xyz="0 0 0"/>
      <inertia ixx="0.0001" ixy="0" ixz="0" iyy="0.0001" iyz="0" izz="0.0002"/>
      <gravity>0</gravity>
      <self_collide>0</self_collide>
    </inertial>
    <visual>
      <origin rpy="0 0 0" xyz="0 0 0"/>
      <geometry>
        <mesh filename="file:///home/elu1652/ros2_ws/src/rover-2025/install/sim/share/sim/model/meshes/Link4.stl"/>
      </geometry>
    </visual>
    <collision>
      <origin rpy="0 0 0" xyz="0 0 0"/>
      <geometry>
        <mesh filename="file:///home/elu1652/ros2_ws/src/rover-2025/install/sim/share/sim/model/meshes/collision_Link4.stl"/>
      </geometry>
    </collision>
  </link>
  <joint name="joint_wrist_roll" type="revolute">
    <origin rpy="0 0 0" xyz="0.034 0 0"/>
    <parent link="link_4_wrist_pitch_wrist_roll"/>
    <child link="link_5_wrist_roll_end_effector"/>
    <axis xyz="1 0 0"/>
    <limit effort="10.0" lower="-3.141592" upper="3.141592" velocity="2.61799"/>
    <dynamics damping="0.5"/>
  </joint>
  <link name="link_5_wrist_roll_end_effector">
    <inertial>
      <mass value="0.1"/>
      <origin rpy="0 0 0" xyz="0 0 0"/>
      <inertia ixx="0.0001" ixy="0" ixz="0" iyy="0.0001" iyz="0" izz="0.0002"/>
      <gravity>0</gravity>
      <self_collide>0</self_collide>
    </inertial>
    <visual>
      <origin rpy="0 0 0" xyz="0 0 0"/>
      <geometry>
        <mesh filename="file:///home/elu1652/ros2_ws/src/rover-2025/install/sim/share/sim/model/meshes/Link5.stl"/>
      </geometry>
    </visual>
    <collision>
      <origin rpy="0 0 0" xyz="0 0 0"/>
      <geometry>
        <mesh filename="file:///home/elu1652/ros2_ws/src/rover-2025/install/sim/share/sim/model/meshes/collision_Link5.stl"/>
      </geometry>
    </collision>
  </link>
  <joint name="joint_end_effector" type="revolute">
    <origin rpy="0 0 1.570796327" xyz="0.050 -0.045 -0.01"/>
    <parent link="link_5_wrist_roll_end_effector"/>
    <child link="link_6_end_effector_1"/>
    <axis xyz="0 0 1"/>
    <limit effort="10.0" lower="-3.141592" upper="3.141592" velocity="2.61799"/>
    <dynamics damping="0.5"/>
  </joint>
  <joint name="joint_7" type="revolute">
    <origin rpy="0 3.141592 1.570796327" xyz="0.050 0.045 -0.01"/>
    <parent link="link_5_wrist_roll_end_effector"/>
    <child link="link_7_end_effector_2"/>
    <axis xyz="0 0 1"/>
    <limit effort="10.0" lower="-3.141592" upper="3.141592" velocity="2.61799"/>
    <dynamics damping="0.5"/>
  </joint>
  <link name="link_6_end_effector_1">
    <inertial>
      <mass value="0.1"/>
      <origin rpy="0 0 0" xyz="0 0 0"/>
      <inertia ixx="0.0001" ixy="0" ixz="0" iyy="0.0001" iyz="0" izz="0.0002"/>
    </inertial>
    <visual>
      <origin rpy="0 0 0" xyz="0 0 0"/>
      <geometry>
        <mesh filename="file:///home/elu1652/ros2_ws/src/rover-2025/install/sim/share/sim/model/meshes/finger.stl"/>
      </geometry>
    </visual>
    <collision>
      <origin rpy="0 0 0" xyz="0 0 0"/>
      <geometry>
        <box size="0.1 0.1 0.1"/>
      </geometry>
    </collision>
  </link>
  <link name="link_7_end_effector_2">
    <inertial>
      <mass value="0.1"/>
      <origin rpy="0 0 0" xyz="0 0 0"/>
      <inertia ixx="0.0001" ixy="0" ixz="0" iyy="0.0001" iyz="0" izz="0.0002"/>
    </inertial>
    <visual>
      <origin rpy="0 0 0" xyz="0 0 0"/>
      <geometry>
        <mesh filename="file:///home/elu1652/ros2_ws/src/rover-2025/install/sim/share/sim/model/meshes/finger.stl"/>
      </geometry>
    </visual>
    <collision>
      <origin rpy="0 0 0" xyz="0 0 0"/>
      <geometry>
        <box size="0.1 0.1 0.1"/>
      </geometry>
    </collision>
  </link>
  <!-- Prevent crash in ign gazebo -->
  <disable_collisions link1="chassis_link" link2="link_0_base_waist" reason="Adjacent"/>
  <disable_collisions link1="link_0_base_waist" link2="link_1_waist_shoulder" reason="Adjacent"/>
  <disable_collisions link1="link_1_waist_shoulder" link2="link_2_shoulder_elbow" reason="Adjacent"/>
  <disable_collisions link1="link_2_shoulder_elbow" link2="link_3_elbow_wrist_pitch" reason="Adjacent"/>
  <disable_collisions link1="link_3_elbow_wrist_pitch" link2="link_4_wrist_pitch_wrist_roll" reason="Adjacent"/>
  <disable_collisions link1="link_4_wrist_pitch_wrist_roll" link2="link_5_wrist_roll_end_effector" reason="Adjacent"/>
  <disable_collisions link1="link_5_wrist_roll_end_effector" link2="link_6_end_effector_1" reason="Adjacent"/>
  <disable_collisions link1="link_5_wrist_roll_end_effector" link2="link_7_end_effector_2" reason="Adjacent"/>
  <disable_collisions link1="link_6_end_effector_1" link2="link_7_end_effector_2" reason="Adjacent"/>
  <!-- Gazebo Plugins -->
  <gazebo>
    <!-- Drive control -->
    <plugin filename="ignition-gazebo-diff-drive-system" name="ignition::gazebo::systems::DiffDrive">
      <num_wheel_pairs>2</num_wheel_pairs>
      <!-- Wheel Information -->
      <left_joint>lf_wheel</left_joint>
      <left_joint>lb_wheel</left_joint>
      <right_joint>rf_wheel</right_joint>
      <right_joint>rb_wheel</right_joint>
      <wheel_separation>0.63255</wheel_separation>
      <wheel_radius>0.1</wheel_radius>
      <!-- Limits -->
      <max_linear_acceleration>1</max_linear_acceleration>
      <min_linear_acceleration>-1</min_linear_acceleration>
      <max_angular_acceleration>2</max_angular_acceleration>
      <min_angular_acceleration>-2</min_angular_acceleration>
      <max_linear_velocity>0.5</max_linear_velocity>
      <min_linear_velocity>-0.5</min_linear_velocity>
      <!-- Output -->
      <frame_id>odom</frame_id>
      <child_frame_id>base_link</child_frame_id>
      <!-- Topics -->
      <topic>/cmd_vel</topic>
      <odom_topic>/odometry/wheels</odom_topic>
      <tf_topic>/tf_gazebo</tf_topic>
    </plugin>
    <plugin filename="ignition-gazebo-joint-state-publisher-system" name="ignition::gazebo::systems::JointStatePublisher">
      <topic>/joint_states</topic>
    </plugin>
    <!-- TODO FIXME doesn't work yet -->
    <!-- IMU -->
    <!-- <plugin filename="libignition-gazebo-imu-system" name="ignition::gazebo::systems::Imu"
        />
        <sensor name="imu" type="imu">
            <always_on>1</always_on>
            <update_rate>50</update_rate>
            <visualize>true</visualize>
            <topic>/imu/data</topic>
            <enable_metrics>true</enable_metrics>
            <ignition_frame_id>imu_link</ignition_frame_id>
        </sensor> -->
  </gazebo>
</robot>
