<?xml version="1.0"?>

<robot name="mr_arm" xmlns:xacro="http://ros.org/wiki/xacro">
  <xacro:macro name="MR_arm" params="parent_link *joint_pose">
    <!-- Base link is the center of the robot's bottom plate -->

    <joint name="MR_arm_joint"
      type="fixed">
      <parent link="${parent_link}" />
      <child link="link_0_base_waist" />
      <xacro:insert_block name="joint_pose" />
    </joint>

    <link name="link_0_base_waist">
      <inertial>
        <mass value="0.1" />
        <origin xyz="0 0 0" rpy="0 0 0" />
        <inertia ixx="0" ixy="0" ixz="0" iyy="0" iyz="0" izz="0" />
        <gravity>0</gravity>
        <self_collide>0</self_collide>
      </inertial>
      <visual>
        <origin xyz="0 0 0" rpy="0 0 0" />
        <geometry>
          <mesh filename="file://$(find sim)/model/meshes/Link0.stl" />
        </geometry>
      </visual>
      <collision>
        <origin xyz="0 0 0" rpy="0 0 0" />
        <geometry>
          <mesh filename="file://$(find sim)/model/meshes/collision_Link0.stl" />
        </geometry>
      </collision>
    </link>

    <joint name="joint_waist" type="revolute">
      <origin xyz="0 0 0" rpy="0 0 0" />
      <parent link="link_0_base_waist" />
      <child link="link_1_waist_shoulder" />
      <axis xyz="0 0 1" />
      <limit effort="10.0" velocity="2.61799" lower="-3.141592" upper="3.141592" />
      <dynamics damping="0.5" />
    </joint>

    <!-- Joint 1 -->
    <link name="link_1_waist_shoulder">
      <inertial>
        <mass value="0.1" />
        <origin xyz="0 0 0" rpy="0 0 0" />
        <inertia ixx="0" ixy="0" ixz="0" iyy="0" iyz="0" izz="0" />
        <gravity>0</gravity>
        <self_collide>0</self_collide>
      </inertial>
      <visual>
        <origin xyz="0 0 0" rpy="0 0 0" />
        <geometry>
          <mesh filename="file://$(find sim)/model/meshes/Link1.stl" />
        </geometry>
      </visual>
      <collision>
        <origin xyz="0 0 0" rpy="0 0 0" />
        <geometry>
          <mesh filename="file://$(find sim)/model/meshes/collision_Link1.stl" />
        </geometry>
      </collision>
    </link>

    <joint
      name="joint_shoulder" type="revolute">
      <origin xyz="0 0 0.0575" rpy="0 0 0" />
      <parent link="link_1_waist_shoulder" />
      <child link="link_2_shoulder_elbow" />
      <axis xyz="0 1 0" />
      <limit effort="10.0" velocity="2.61799" lower="-1.570796327" upper="1.570796327" />
      <dynamics damping="0.5" />
    </joint>


    <link name="link_2_shoulder_elbow">
      <inertial>
        <mass value="0.1" />
        <origin xyz="0 0 0" rpy="0 0 0" />
        <inertia ixx="0" ixy="0" ixz="0" iyy="0" iyz="0" izz="0" />
        <gravity>0</gravity>
        <self_collide>0</self_collide>
      </inertial>
      <visual>
        <origin xyz="0 0 0" rpy="0 0 0" />
        <geometry>
          <mesh filename="file://$(find sim)/model/meshes/Link2.stl" />
        </geometry>
      </visual>
      <collision>
        <origin xyz="0 0 0" rpy="0 0 0" />
        <geometry>
          <mesh filename="file://$(find sim)/model/meshes/collision_Link2.stl" />
        </geometry>
      </collision>
    </link>

    <joint
      name="joint_elbow" type="revolute">
      <origin xyz="0 0 0.5" rpy="0 0 0" />
      <parent link="link_2_shoulder_elbow" />
      <child link="link_3_elbow_wrist_pitch" />
      <axis xyz="0 1 0" />
      <limit effort="10.0" velocity="2.61799" lower="-1.570796327" upper="1.570796327" />
      <dynamics damping="0.5" />
    </joint>


    <link name="link_3_elbow_wrist_pitch">
      <inertial>
        <mass value="0.1" />
        <origin xyz="0 0 0" rpy="0 0 0" />
        <inertia ixx="0" ixy="0" ixz="0" iyy="0" iyz="0" izz="0" />
        <gravity>0</gravity>
        <self_collide>0</self_collide>
      </inertial>
      <visual>
        <origin xyz="0 0 0" rpy="0 0 0" />
        <geometry>
          <mesh filename="file://$(find sim)/model/meshes/Link3.stl" />
        </geometry>
      </visual>
      <collision>
        <origin xyz="0 0 0" rpy="0 0 0" />
        <geometry>
          <mesh filename="file://$(find sim)/model/meshes/collision_Link3.stl" />
        </geometry>
      </collision>
    </link>

    <joint
      name="joint_wrist_pitch" type="revolute">
      <origin xyz="0.4 0 0" rpy="0 0 0" />
      <parent link="link_3_elbow_wrist_pitch" />
      <child link="link_4_wrist_pitch_wrist_roll" />
      <axis xyz="0 1 0" />
      <limit effort="10.0" velocity="2.61799" lower="-1.570796327" upper="1.570796327" />
      <dynamics damping="0.5" />
    </joint>


    <link name="link_4_wrist_pitch_wrist_roll">
      <inertial>
        <mass value="0.1" />
        <origin xyz="0 0 0" rpy="0 0 0" />
        <inertia ixx="0" ixy="0" ixz="0" iyy="0" iyz="0" izz="0" />
        <gravity>0</gravity>
        <self_collide>0</self_collide>
      </inertial>
      <visual>
        <origin xyz="0 0 0" rpy="0 0 0" />
        <geometry>
          <mesh filename="file://$(find sim)/model/meshes/Link4.stl" />
        </geometry>
      </visual>
      <collision>
        <origin xyz="0 0 0" rpy="0 0 0" />
        <geometry>
          <mesh filename="file://$(find sim)/model/meshes/collision_Link4.stl" />
        </geometry>
      </collision>
    </link>

    <joint
      name="joint_wrist_roll" type="revolute">
      <origin xyz="0.034 0 0" rpy="0 0 0" />
      <parent link="link_4_wrist_pitch_wrist_roll" />
      <child link="link_5_wrist_roll_end_effector" />
      <axis xyz="1 0 0" />
      <limit effort="10.0" velocity="2.61799" lower="-3.141592" upper="3.141592" />
      <dynamics damping="0.5" />
    </joint>


    <link name="link_5_wrist_roll_end_effector">
      <inertial>
        <mass value="0.1" />
        <origin xyz="0 0 0" rpy="0 0 0" />
        <inertia ixx="0" ixy="0" ixz="0" iyy="0" iyz="0" izz="0" />
        <gravity>0</gravity>
        <self_collide>0</self_collide>
      </inertial>
      <visual>
        <origin xyz="0 0 0" rpy="0 0 0" />
        <geometry>
          <mesh filename="file://$(find sim)/model/meshes/Link5.stl" />
        </geometry>
      </visual>
      <collision>
        <origin xyz="0 0 0" rpy="0 0 0" />
        <geometry>
          <mesh filename="file://$(find sim)/model/meshes/collision_Link5.stl" />
        </geometry>
      </collision>
    </link>


    <joint
      name="joint_end_effector" type="revolute">
      <origin xyz="0.050 -0.045 -0.01" rpy="0 0 1.570796327" />
      <parent link="link_5_wrist_roll_end_effector" />
      <child link="link_6_end_effector_1" />
      <axis xyz="0 0 1" />
      <limit effort="10.0" velocity="2.61799" lower="-3.141592" upper="3.141592" />
      <dynamics damping="0.5" />
    </joint>

    <joint name="joint_7" type="revolute">
      <origin xyz="0.050 0.045 -0.01" rpy="0 3.141592 1.570796327" />
      <parent link="link_5_wrist_roll_end_effector" />
      <child link="link_7_end_effector_2" />
      <axis xyz="0 0 1" />
      <limit effort="10.0" velocity="2.61799" lower="-3.141592" upper="3.141592" />
      <dynamics damping="0.5" />
    </joint>


    <link name="link_6_end_effector_1">
      <inertial>
        <mass value="0.1" />
        <origin xyz="0 0 0" rpy="0 0 0" />
        <inertia ixx="0" ixy="0" ixz="0" iyy="0" iyz="0" izz="0" />
      </inertial>
      <visual>
        <origin xyz="0 0 0" rpy="0 0 0" />
        <geometry>
          <mesh filename="file://$(find sim)/model/meshes/finger.stl" />
        </geometry>
      </visual>
      <collision>
        <origin xyz="0 0 0" rpy="0 0 0" />
        <geometry>
          <box size="0.1 0.1 0.1" />
        </geometry>
      </collision>
    </link>


    <link
      name="link_7_end_effector_2">
      <inertial>
        <mass value="0.1" />
        <origin xyz="0 0 0" rpy="0 0 0" />
        <inertia ixx="0" ixy="0" ixz="0" iyy="0" iyz="0" izz="0" />
      </inertial>
      <visual>
        <origin xyz="0 0 0" rpy="0 0 0" />
        <geometry>
          <mesh filename="file://$(find sim)/model/meshes/finger.stl" />
        </geometry>
      </visual>
      <collision>
        <origin xyz="0 0 0" rpy="0 0 0" />
        <geometry>
          <box size="0.1 0.1 0.1" />
        </geometry>
      </collision>
    </link>

    <!-- Prevent crash in ign gazebo -->
    <disable_collisions link1="${parent_link}" link2="link_0_base_waist"
      reason="Adjacent" />
    <disable_collisions link1="link_0_base_waist" link2="link_1_waist_shoulder"
      reason="Adjacent" />
    <disable_collisions link1="link_1_waist_shoulder" link2="link_2_shoulder_elbow"
      reason="Adjacent" />
    <disable_collisions link1="link_2_shoulder_elbow" link2="link_3_elbow_wrist_pitch"
      reason="Adjacent" />
    <disable_collisions link1="link_3_elbow_wrist_pitch" link2="link_4_wrist_pitch_wrist_roll"
      reason="Adjacent" />
    <disable_collisions link1="link_4_wrist_pitch_wrist_roll" link2="link_5_wrist_roll_end_effector"
      reason="Adjacent" />
    <disable_collisions link1="link_5_wrist_roll_end_effector" link2="link_6_end_effector_1"
      reason="Adjacent" />
    <disable_collisions link1="link_5_wrist_roll_end_effector" link2="link_7_end_effector_2"
      reason="Adjacent" />
    <disable_collisions link1="link_6_end_effector_1" link2="link_7_end_effector_2"
      reason="Adjacent" />

  </xacro:macro>
</robot>